Workbook

Sheet README
A1: Simple portfolio tracker - historical data loaded through Mar/26
A3: 1) Assets: from Apr/26 onward, write your current MONTHLY PAC in column F. Savings are NOT part of PAC.
A4: 2) Transactions_PAC: from Apr/26 onward, each ETF has 1 planned MONTHLY PAC row per month.
A5: 3) In Transactions_PAC, Status works like this:
A6: - Auto = use the planned monthly PAC
A7: - No = skip that month
A8: - Edited = write your real amount in Actual_Amount
A9: 4) Transactions_Manual: use only for extra buys/sells outside the normal PAC.
A10: 5) Month_End: at month end, update Savings + each ETF value.

Sheet Assets
A1: Asset | B1: Category | C1: Subcategory | D1: Bucket | E1: Active? | F1: Monthly_PAC | G1: Note | I1: Note
A2: Core MSCI World | B2: ETF | C2: ETF Stock | D2: Stocks | E2: Yes | F2: 0 | G2: Set Apr/26 onward monthly PAC here once finalized
A3: AI & Big Data | B3: ETF | C3: ETF Stock | D3: Stocks | E3: Yes | F3: 0
A4: Physical Gold | B4: ETF | C4: ETF Gold | D4: Defensive | E4: Yes | F4: 0
A5: Global Gov Bond | B5: ETF | C5: ETF Bond | D5: Defensive | E5: Yes | F5: 0
A6: Core EUR Corp Bond | B6: ETF | C6: ETF Bond | D6: Defensive | E6: Yes | F6: 0
A7: MSCI World Value | B7: ETF | C7: ETF Stock | D7: Stocks | E7: Yes | F7: 0
A8: MSCI EM | B8: ETF | C8: ETF Stock | D8: Stocks | E8: Yes | F8: 0
A9: Defence Tech | B9: ETF | C9: ETF Stock | D9: Stocks | E9: Yes | F9: 0
A10: Savings | B10: Savings | C10: Savings TR | D10: Savings | E10: Yes | F10: 0

Sheet Transactions_PAC
A1: Tx_Date | B1: Month | C1: Asset | D1: Tx_Type | E1: Planned_Amount | F1: Status | G1: Actual_Amount | H1: Flow_Used | I1: Notes
A2: 46113 | B2: =DATE(YEAR(A2),MONTH(A2),1) | C2: Core MSCI World | D2: PAC | E2: =IFERROR(VLOOKUP(C2,Assets!$A:$F,6,FALSE),0) | F2: Auto | H2: =IF(F2="No",0,IF(F2="Edited",IF(G2="",E2,G2),E2))
A3: 46113 | B3: =DATE(YEAR(A3),MONTH(A3),1) | C3: AI & Big Data | D3: PAC | E3: =IFERROR(VLOOKUP(C3,Assets!$A:$F,6,FALSE),0) | F3: Auto | H3: =IF(F3="No",0,IF(F3="Edited",IF(G3="",E3,G3),E3))
A4: 46113 | B4: =DATE(YEAR(A4),MONTH(A4),1) | C4: Physical Gold | D4: PAC | E4: =IFERROR(VLOOKUP(C4,Assets!$A:$F,6,FALSE),0) | F4: Auto | H4: =IF(F4="No",0,IF(F4="Edited",IF(G4="",E4,G4),E4))
A5: 46113 | B5: =DATE(YEAR(A5),MONTH(A5),1) | C5: Global Gov Bond | D5: PAC | E5: =IFERROR(VLOOKUP(C5,Assets!$A:$F,6,FALSE),0) | F5: Auto | H5: =IF(F5="No",0,IF(F5="Edited",IF(G5="",E5,G5),E5))
A6: 46113 | B6: =DATE(YEAR(A6),MONTH(A6),1) | C6: Core EUR Corp Bond | D6: PAC | E6: =IFERROR(VLOOKUP(C6,Assets!$A:$F,6,FALSE),0) | F6: Auto | H6: =IF(F6="No",0,IF(F6="Edited",IF(G6="",E6,G6),E6))
A7: 46113 | B7: =DATE(YEAR(A7),MONTH(A7),1) | C7: MSCI World Value | D7: PAC | E7: =IFERROR(VLOOKUP(C7,Assets!$A:$F,6,FALSE),0) | F7: Auto | H7: =IF(F7="No",0,IF(F7="Edited",IF(G7="",E7,G7),E7))
A8: 46113 | B8: =DATE(YEAR(A8),MONTH(A8),1) | C8: MSCI EM | D8: PAC | E8: =IFERROR(VLOOKUP(C8,Assets!$A:$F,6,FALSE),0) | F8: Auto | H8: =IF(F8="No",0,IF(F8="Edited",IF(G8="",E8,G8),E8))
A9: 46113 | B9: =DATE(YEAR(A9),MONTH(A9),1) | C9: Defence Tech | D9: PAC | E9: =IFERROR(VLOOKUP(C9,Assets!$A:$F,6,FALSE),0) | F9: Auto | H9: =IF(F9="No",0,IF(F9="Edited",IF(G9="",E9,G9),E9))
A10: 46143 | B10: =DATE(YEAR(A10),MONTH(A10),1) | C10: Core MSCI World | D10: PAC | E10: =IFERROR(VLOOKUP(C10,Assets!$A:$F,6,FALSE),0) | F10: Auto | H10: =IF(F10="No",0,IF(F10="Edited",IF(G10="",E10,G10),E10))
A11: 46143 | B11: =DATE(YEAR(A11),MONTH(A11),1) | C11: AI & Big Data | D11: PAC | E11: =IFERROR(VLOOKUP(C11,Assets!$A:$F,6,FALSE),0) | F11: Auto | H11: =IF(F11="No",0,IF(F11="Edited",IF(G11="",E11,G11),E11))
A12: 46143 | B12: =DATE(YEAR(A12),MONTH(A12),1) | C12: Physical Gold | D12: PAC | E12: =IFERROR(VLOOKUP(C12,Assets!$A:$F,6,FALSE),0) | F12: Auto | H12: =IF(F12="No",0,IF(F12="Edited",IF(G12="",E12,G12),E12))
A13: 46143 | B13: =DATE(YEAR(A13),MONTH(A13),1) | C13: Global Gov Bond | D13: PAC | E13: =IFERROR(VLOOKUP(C13,Assets!$A:$F,6,FALSE),0) | F13: Auto | H13: =IF(F13="No",0,IF(F13="Edited",IF(G13="",E13,G13),E13))
... A1225: 50740 | B1225: =DATE(YEAR(A1225),MONTH(A1225),1) | C1225: Defence Tech | D1225: PAC | E1225: =IFERROR(VLOOKUP(C1225,Assets!$A:$F,6,FALSE),0) | F1225: Auto | H1225: =IF(F1225="No",0,IF(F1225="Edited",IF(G1225="",E1225,G1225),E1225))

Sheet Transactions_Manual
A1: Tx_Date | B1: Month | C1: Asset | D1: Tx_Type | E1: Amount | F1: Notes
A2: 45931 | B2: =IF(A2="","",DATE(YEAR(A2),MONTH(A2),1)) | C2: Core MSCI World | D2: Historical Flow | E2: 690.4 | F2: Imported from your old tracker
A3: 45931 | B3: =IF(A3="","",DATE(YEAR(A3),MONTH(A3),1)) | C3: AI & Big Data | D3: Historical Flow | E3: 101 | F3: Imported from your old tracker
A4: 45931 | B4: =IF(A4="","",DATE(YEAR(A4),MONTH(A4),1)) | C4: Physical Gold | D4: Historical Flow | E4: 70 | F4: Imported from your old tracker
A5: 45931 | B5: =IF(A5="","",DATE(YEAR(A5),MONTH(A5),1)) | C5: Global Gov Bond | D5: Historical Flow | E5: 52 | F5: Imported from your old tracker
A6: 45931 | B6: =IF(A6="","",DATE(YEAR(A6),MONTH(A6),1)) | C6: Core EUR Corp Bond | D6: Historical Flow | E6: 54 | F6: Imported from your old tracker
A7: 45931 | B7: =IF(A7="","",DATE(YEAR(A7),MONTH(A7),1)) | C7: MSCI World Value | D7: Historical Flow | E7: 196.99 | F7: Imported from your old tracker
A8: 45931 | B8: =IF(A8="","",DATE(YEAR(A8),MONTH(A8),1)) | C8: MSCI EM | D8: Historical Flow | E8: 44 | F8: Imported from your old tracker
A9: 45931 | B9: =IF(A9="","",DATE(YEAR(A9),MONTH(A9),1)) | C9: Defence Tech | D9: Historical Flow | E9: 0 | F9: Imported from your old tracker
A10: 45962 | B10: =IF(A10="","",DATE(YEAR(A10),MONTH(A10),1)) | C10: Core MSCI World | D10: Historical Flow | E10: 486 | F10: Imported from your old tracker
A11: 45962 | B11: =IF(A11="","",DATE(YEAR(A11),MONTH(A11),1)) | C11: AI & Big Data | D11: Historical Flow | E11: 0 | F11: Imported from your old tracker
A12: 45962 | B12: =IF(A12="","",DATE(YEAR(A12),MONTH(A12),1)) | C12: Physical Gold | D12: Historical Flow | E12: 70 | F12: Imported from your old tracker
A13: 45962 | B13: =IF(A13="","",DATE(YEAR(A13),MONTH(A13),1)) | C13: Global Gov Bond | D13: Historical Flow | E13: 52 | F13: Imported from your old tracker
... A49: 46082 | B49: =IF(A49="","",DATE(YEAR(A49),MONTH(A49),1)) | C49: Defence Tech | D49: Historical Flow | E49: 0 | F49: Imported from your old tracker
D50: Extra Buy
D51: Extra Buy
D52: Extra Buy
D53: Extra Buy
D54: Extra Buy
D55: Extra Buy
D56: Extra Buy
D57: Extra Buy
D58: Extra Buy
D59: Extra Buy
D60: Extra Buy
D61: Extra Buy
... D299: Extra Buy

Sheet Month_End
A1: Month | B1: Asset | C1: Category | D1: End_Value
A2: 45931 | B2: Core MSCI World | C2: =IFERROR(VLOOKUP(B2,Assets!$A:$B,2,FALSE),"") | D2: 11058
A3: 45931 | B3: AI & Big Data | C3: =IFERROR(VLOOKUP(B3,Assets!$A:$B,2,FALSE),"") | D3: 3265
A4: 45931 | B4: Physical Gold | C4: =IFERROR(VLOOKUP(B4,Assets!$A:$B,2,FALSE),"") | D4: 1792
A5: 45931 | B5: Global Gov Bond | C5: =IFERROR(VLOOKUP(B5,Assets!$A:$B,2,FALSE),"") | D5: 1456
A6: 45931 | B6: Core EUR Corp Bond | C6: =IFERROR(VLOOKUP(B6,Assets!$A:$B,2,FALSE),"") | D6: 1456
A7: 45931 | B7: MSCI World Value | C7: =IFERROR(VLOOKUP(B7,Assets!$A:$B,2,FALSE),"") | D7: 1439
A8: 45931 | B8: MSCI EM | C8: =IFERROR(VLOOKUP(B8,Assets!$A:$B,2,FALSE),"") | D8: 1233
A9: 45931 | B9: Defence Tech | C9: =IFERROR(VLOOKUP(B9,Assets!$A:$B,2,FALSE),"") | D9: 483.2
A10: 45931 | B10: Savings | C10: =IFERROR(VLOOKUP(B10,Assets!$A:$B,2,FALSE),"") | D10: 34010.01
A11: 45962 | B11: Core MSCI World | C11: =IFERROR(VLOOKUP(B11,Assets!$A:$B,2,FALSE),"") | D11: 11303
A12: 45962 | B12: AI & Big Data | C12: =IFERROR(VLOOKUP(B12,Assets!$A:$B,2,FALSE),"") | D12: 3177
A13: 45962 | B13: Physical Gold | C13: =IFERROR(VLOOKUP(B13,Assets!$A:$B,2,FALSE),"") | D13: 1875
... A55: 46082 | B55: Savings | C55: =IFERROR(VLOOKUP(B55,Assets!$A:$B,2,FALSE),"") | D55: 39883
A56: 46113 | B56: Core MSCI World | C56: =IFERROR(VLOOKUP(B56,Assets!$A:$B,2,FALSE),"")
A57: 46113 | B57: AI & Big Data | C57: =IFERROR(VLOOKUP(B57,Assets!$A:$B,2,FALSE),"")
A58: 46113 | B58: Physical Gold | C58: =IFERROR(VLOOKUP(B58,Assets!$A:$B,2,FALSE),"")
A59: 46113 | B59: Global Gov Bond | C59: =IFERROR(VLOOKUP(B59,Assets!$A:$B,2,FALSE),"")
A60: 46113 | B60: Core EUR Corp Bond | C60: =IFERROR(VLOOKUP(B60,Assets!$A:$B,2,FALSE),"")
A61: 46113 | B61: MSCI World Value | C61: =IFERROR(VLOOKUP(B61,Assets!$A:$B,2,FALSE),"")
A62: 46113 | B62: MSCI EM | C62: =IFERROR(VLOOKUP(B62,Assets!$A:$B,2,FALSE),"")
A63: 46113 | B63: Defence Tech | C63: =IFERROR(VLOOKUP(B63,Assets!$A:$B,2,FALSE),"")
A64: 46113 | B64: Savings | C64: =IFERROR(VLOOKUP(B64,Assets!$A:$B,2,FALSE),"")
A65: 46143 | B65: Core MSCI World | C65: =IFERROR(VLOOKUP(B65,Assets!$A:$B,2,FALSE),"")
A66: 46143 | B66: AI & Big Data | C66: =IFERROR(VLOOKUP(B66,Assets!$A:$B,2,FALSE),"")
A67: 46143 | B67: Physical Gold | C67: =IFERROR(VLOOKUP(B67,Assets!$A:$B,2,FALSE),"")
... A352: 47088 | B352: Savings | C352: =IFERROR(VLOOKUP(B352,Assets!$A:$B,2,FALSE),"")

Sheet Summary
A1: Asset | B1: Month | C1: End_Value | D1: Flow_PAC | E1: Flow_Manual | F1: Total_Flow | G1: Prev_End | H1: PnL_€ | I1: Perf_%
A2: Core MSCI World | B2: 45931 | C2: =SUMIFS(Month_End!$D:$D,Month_End!$A:$A,B2,Month_End!$B:$B,A2) | D2: =SUMIFS(Transactions_PAC!$H:$H,Transactions_PAC!$B:$B,B2,Transactions_PAC!$C:$C,A2) | E2: =SUMIFS(Transactions_Manual!$E:$E,Transactions_Manual!$B:$B,B2,Transactions_Manual!$C:$C,A2) | F2: =D2+E2 | H2: =IF(OR(G2="",A2="Savings"),"",C2-G2-F2) | I2: =IF(OR(H2="",G2=0), "", H2/G2)
A3: Core MSCI World | B3: 45962 | C3: =SUMIFS(Month_End!$D:$D,Month_End!$A:$A,B3,Month_End!$B:$B,A3) | D3: =SUMIFS(Transactions_PAC!$H:$H,Transactions_PAC!$B:$B,B3,Transactions_PAC!$C:$C,A3) | E3: =SUMIFS(Transactions_Manual!$E:$E,Transactions_Manual!$B:$B,B3,Transactions_Manual!$C:$C,A3) | F3: =D3+E3 | G3: =C2 | H3: =IF(OR(G3="",A3="Savings"),"",C3-G3-F3) | I3: =IF(OR(H3="",G3=0), "", H3/G3)
A4: Core MSCI World | B4: 45992 | C4: =SUMIFS(Month_End!$D:$D,Month_End!$A:$A,B4,Month_End!$B:$B,A4) | D4: =SUMIFS(Transactions_PAC!$H:$H,Transactions_PAC!$B:$B,B4,Transactions_PAC!$C:$C,A4) | E4: =SUMIFS(Transactions_Manual!$E:$E,Transactions_Manual!$B:$B,B4,Transactions_Manual!$C:$C,A4) | F4: =D4+E4 | G4: =C3 | H4: =IF(OR(G4="",A4="Savings"),"",C4-G4-F4) | I4: =IF(OR(H4="",G4=0), "", H4/G4)
A5: Core MSCI World | B5: 46023 | C5: =SUMIFS(Month_End!$D:$D,Month_End!$A:$A,B5,Month_End!$B:$B,A5) | D5: =SUMIFS(Transactions_PAC!$H:$H,Transactions_PAC!$B:$B,B5,Transactions_PAC!$C:$C,A5) | E5: =SUMIFS(Transactions_Manual!$E:$E,Transactions_Manual!$B:$B,B5,Transactions_Manual!$C:$C,A5) | F5: =D5+E5 | G5: =C4 | H5: =IF(OR(G5="",A5="Savings"),"",C5-G5-F5) | I5: =IF(OR(H5="",G5=0), "", H5/G5)
A6: Core MSCI World | B6: 46054 | C6: =SUMIFS(Month_End!$D:$D,Month_End!$A:$A,B6,Month_End!$B:$B,A6) | D6: =SUMIFS(Transactions_PAC!$H:$H,Transactions_PAC!$B:$B,B6,Transactions_PAC!$C:$C,A6) | E6: =SUMIFS(Transactions_Manual!$E:$E,Transactions_Manual!$B:$B,B6,Transactions_Manual!$C:$C,A6) | F6: =D6+E6 | G6: =C5 | H6: =IF(OR(G6="",A6="Savings"),"",C6-G6-F6) | I6: =IF(OR(H6="",G6=0), "", H6/G6)
A7: Core MSCI World | B7: 46082 | C7: =SUMIFS(Month_End!$D:$D,Month_End!$A:$A,B7,Month_End!$B:$B,A7) | D7: =SUMIFS(Transactions_PAC!$H:$H,Transactions_PAC!$B:$B,B7,Transactions_PAC!$C:$C,A7) | E7: =SUMIFS(Transactions_Manual!$E:$E,Transactions_Manual!$B:$B,B7,Transactions_Manual!$C:$C,A7) | F7: =D7+E7 | G7: =C6 | H7: =IF(OR(G7="",A7="Savings"),"",C7-G7-F7) | I7: =IF(OR(H7="",G7=0), "", H7/G7)
A8: Core MSCI World | B8: 46113 | C8: =SUMIFS(Month_End!$D:$D,Month_End!$A:$A,B8,Month_End!$B:$B,A8) | D8: =SUMIFS(Transactions_PAC!$H:$H,Transactions_PAC!$B:$B,B8,Transactions_PAC!$C:$C,A8) | E8: =SUMIFS(Transactions_Manual!$E:$E,Transactions_Manual!$B:$B,B8,Transactions_Manual!$C:$C,A8) | F8: =D8+E8 | G8: =C7 | H8: =IF(OR(G8="",A8="Savings"),"",C8-G8-F8) | I8: =IF(OR(H8="",G8=0), "", H8/G8)
A9: Core MSCI World | B9: 46143 | C9: =SUMIFS(Month_End!$D:$D,Month_End!$A:$A,B9,Month_End!$B:$B,A9) | D9: =SUMIFS(Transactions_PAC!$H:$H,Transactions_PAC!$B:$B,B9,Transactions_PAC!$C:$C,A9) | E9: =SUMIFS(Transactions_Manual!$E:$E,Transactions_Manual!$B:$B,B9,Transactions_Manual!$C:$C,A9) | F9: =D9+E9 | G9: =C8 | H9: =IF(OR(G9="",A9="Savings"),"",C9-G9-F9) | I9: =IF(OR(H9="",G9=0), "", H9/G9)
A10: Core MSCI World | B10: 46174 | C10: =SUMIFS(Month_End!$D:$D,Month_End!$A:$A,B10,Month_End!$B:$B,A10) | D10: =SUMIFS(Transactions_PAC!$H:$H,Transactions_PAC!$B:$B,B10,Transactions_PAC!$C:$C,A10) | E10: =SUMIFS(Transactions_Manual!$E:$E,Transactions_Manual!$B:$B,B10,Transactions_Manual!$C:$C,A10) | F10: =D10+E10 | G10: =C9 | H10: =IF(OR(G10="",A10="Savings"),"",C10-G10-F10) | I10: =IF(OR(H10="",G10=0), "", H10/G10)
A11: Core MSCI World | B11: 46204 | C11: =SUMIFS(Month_End!$D:$D,Month_End!$A:$A,B11,Month_End!$B:$B,A11) | D11: =SUMIFS(Transactions_PAC!$H:$H,Transactions_PAC!$B:$B,B11,Transactions_PAC!$C:$C,A11) | E11: =SUMIFS(Transactions_Manual!$E:$E,Transactions_Manual!$B:$B,B11,Transactions_Manual!$C:$C,A11) | F11: =D11+E11 | G11: =C10 | H11: =IF(OR(G11="",A11="Savings"),"",C11-G11-F11) | I11: =IF(OR(H11="",G11=0), "", H11/G11)
A12: Core MSCI World | B12: 46235 | C12: =SUMIFS(Month_End!$D:$D,Month_End!$A:$A,B12,Month_End!$B:$B,A12) | D12: =SUMIFS(Transactions_PAC!$H:$H,Transactions_PAC!$B:$B,B12,Transactions_PAC!$C:$C,A12) | E12: =SUMIFS(Transactions_Manual!$E:$E,Transactions_Manual!$B:$B,B12,Transactions_Manual!$C:$C,A12) | F12: =D12+E12 | G12: =C11 | H12: =IF(OR(G12="",A12="Savings"),"",C12-G12-F12) | I12: =IF(OR(H12="",G12=0), "", H12/G12)
A13: Core MSCI World | B13: 46266 | C13: =SUMIFS(Month_End!$D:$D,Month_End!$A:$A,B13,Month_End!$B:$B,A13) | D13: =SUMIFS(Transactions_PAC!$H:$H,Transactions_PAC!$B:$B,B13,Transactions_PAC!$C:$C,A13) | E13: =SUMIFS(Transactions_Manual!$E:$E,Transactions_Manual!$B:$B,B13,Transactions_Manual!$C:$C,A13) | F13: =D13+E13 | G13: =C12 | H13: =IF(OR(G13="",A13="Savings"),"",C13-G13-F13) | I13: =IF(OR(H13="",G13=0), "", H13/G13)
A14: Core MSCI World | B14: 46296 | C14: =SUMIFS(Month_End!$D:$D,Month_End!$A:$A,B14,Month_End!$B:$B,A14) | D14: =SUMIFS(Transactions_PAC!$H:$H,Transactions_PAC!$B:$B,B14,Transactions_PAC!$C:$C,A14) | E14: =SUMIFS(Transactions_Manual!$E:$E,Transactions_Manual!$B:$B,B14,Transactions_Manual!$C:$C,A14) | F14: =D14+E14 | G14: =C13 | H14: =IF(OR(G14="",A14="Savings"),"",C14-G14-F14) | I14: =IF(OR(H14="",G14=0), "", H14/G14)
... A40: Core MSCI World | B40: 47088 | C40: =SUMIFS(Month_End!$D:$D,Month_End!$A:$A,B40,Month_End!$B:$B,A40) | D40: =SUMIFS(Transactions_PAC!$H:$H,Transactions_PAC!$B:$B,B40,Transactions_PAC!$C:$C,A40) | E40: =SUMIFS(Transactions_Manual!$E:$E,Transactions_Manual!$B:$B,B40,Transactions_Manual!$C:$C,A40) | F40: =D40+E40 | G40: =C39 | H40: =IF(OR(G40="",A40="Savings"),"",C40-G40-F40) | I40: =IF(OR(H40="",G40=0), "", H40/G40)
A41: AI & Big Data | B41: 45931 | C41: =SUMIFS(Month_End!$D:$D,Month_End!$A:$A,B41,Month_End!$B:$B,A41) | D41: =SUMIFS(Transactions_PAC!$H:$H,Transactions_PAC!$B:$B,B41,Transactions_PAC!$C:$C,A41) | E41: =SUMIFS(Transactions_Manual!$E:$E,Transactions_Manual!$B:$B,B41,Transactions_Manual!$C:$C,A41) | F41: =D41+E41 | H41: =IF(OR(G41="",A41="Savings"),"",C41-G41-F41) | I41: =IF(OR(H41="",G41=0), "", H41/G41)
A42: AI & Big Data | B42: 45962 | C42: =SUMIFS(Month_End!$D:$D,Month_End!$A:$A,B42,Month_End!$B:$B,A42) | D42: =SUMIFS(Transactions_PAC!$H:$H,Transactions_PAC!$B:$B,B42,Transactions_PAC!$C:$C,A42) | E42: =SUMIFS(Transactions_Manual!$E:$E,Transactions_Manual!$B:$B,B42,Transactions_Manual!$C:$C,A42) | F42: =D42+E42 | G42: =C41 | H42: =IF(OR(G42="",A42="Savings"),"",C42-G42-F42) | I42: =IF(OR(H42="",G42=0), "", H42/G42)
A43: AI & Big Data | B43: 45992 | C43: =SUMIFS(Month_End!$D:$D,Month_End!$A:$A,B43,Month_End!$B:$B,A43) | D43: =SUMIFS(Transactions_PAC!$H:$H,Transactions_PAC!$B:$B,B43,Transactions_PAC!$C:$C,A43) | E43: =SUMIFS(Transactions_Manual!$E:$E,Transactions_Manual!$B:$B,B43,Transactions_Manual!$C:$C,A43) | F43: =D43+E43 | G43: =C42 | H43: =IF(OR(G43="",A43="Savings"),"",C43-G43-F43) | I43: =IF(OR(H43="",G43=0), "", H43/G43)
A44: AI & Big Data | B44: 46023 | C44: =SUMIFS(Month_End!$D:$D,Month_End!$A:$A,B44,Month_End!$B:$B,A44) | D44: =SUMIFS(Transactions_PAC!$H:$H,Transactions_PAC!$B:$B,B44,Transactions_PAC!$C:$C,A44) | E44: =SUMIFS(Transactions_Manual!$E:$E,Transactions_Manual!$B:$B,B44,Transactions_Manual!$C:$C,A44) | F44: =D44+E44 | G44: =C43 | H44: =IF(OR(G44="",A44="Savings"),"",C44-G44-F44) | I44: =IF(OR(H44="",G44=0), "", H44/G44)
A45: AI & Big Data | B45: 46054 | C45: =SUMIFS(Month_End!$D:$D,Month_End!$A:$A,B45,Month_End!$B:$B,A45) | D45: =SUMIFS(Transactions_PAC!$H:$H,Transactions_PAC!$B:$B,B45,Transactions_PAC!$C:$C,A45) | E45: =SUMIFS(Transactions_Manual!$E:$E,Transactions_Manual!$B:$B,B45,Transactions_Manual!$C:$C,A45) | F45: =D45+E45 | G45: =C44 | H45: =IF(OR(G45="",A45="Savings"),"",C45-G45-F45) | I45: =IF(OR(H45="",G45=0), "", H45/G45)
A46: AI & Big Data | B46: 46082 | C46: =SUMIFS(Month_End!$D:$D,Month_End!$A:$A,B46,Month_End!$B:$B,A46) | D46: =SUMIFS(Transactions_PAC!$H:$H,Transactions_PAC!$B:$B,B46,Transactions_PAC!$C:$C,A46) | E46: =SUMIFS(Transactions_Manual!$E:$E,Transactions_Manual!$B:$B,B46,Transactions_Manual!$C:$C,A46) | F46: =D46+E46 | G46: =C45 | H46: =IF(OR(G46="",A46="Savings"),"",C46-G46-F46) | I46: =IF(OR(H46="",G46=0), "", H46/G46)
A47: AI & Big Data | B47: 46113 | C47: =SUMIFS(Month_End!$D:$D,Month_End!$A:$A,B47,Month_End!$B:$B,A47) | D47: =SUMIFS(Transactions_PAC!$H:$H,Transactions_PAC!$B:$B,B47,Transactions_PAC!$C:$C,A47) | E47: =SUMIFS(Transactions_Manual!$E:$E,Transactions_Manual!$B:$B,B47,Transactions_Manual!$C:$C,A47) | F47: =D47+E47 | G47: =C46 | H47: =IF(OR(G47="",A47="Savings"),"",C47-G47-F47) | I47: =IF(OR(H47="",G47=0), "", H47/G47)
A48: AI & Big Data | B48: 46143 | C48: =SUMIFS(Month_End!$D:$D,Month_End!$A:$A,B48,Month_End!$B:$B,A48) | D48: =SUMIFS(Transactions_PAC!$H:$H,Transactions_PAC!$B:$B,B48,Transactions_PAC!$C:$C,A48) | E48: =SUMIFS(Transactions_Manual!$E:$E,Transactions_Manual!$B:$B,B48,Transactions_Manual!$C:$C,A48) | F48: =D48+E48 | G48: =C47 | H48: =IF(OR(G48="",A48="Savings"),"",C48-G48-F48) | I48: =IF(OR(H48="",G48=0), "", H48/G48)
A49: AI & Big Data | B49: 46174 | C49: =SUMIFS(Month_End!$D:$D,Month_End!$A:$A,B49,Month_End!$B:$B,A49) | D49: =SUMIFS(Transactions_PAC!$H:$H,Transactions_PAC!$B:$B,B49,Transactions_PAC!$C:$C,A49) | E49: =SUMIFS(Transactions_Manual!$E:$E,Transactions_Manual!$B:$B,B49,Transactions_Manual!$C:$C,A49) | F49: =D49+E49 | G49: =C48 | H49: =IF(OR(G49="",A49="Savings"),"",C49-G49-F49) | I49: =IF(OR(H49="",G49=0), "", H49/G49)
A50: AI & Big Data | B50: 46204 | C50: =SUMIFS(Month_End!$D:$D,Month_End!$A:$A,B50,Month_End!$B:$B,A50) | D50: =SUMIFS(Transactions_PAC!$H:$H,Transactions_PAC!$B:$B,B50,Transactions_PAC!$C:$C,A50) | E50: =SUMIFS(Transactions_Manual!$E:$E,Transactions_Manual!$B:$B,B50,Transactions_Manual!$C:$C,A50) | F50: =D50+E50 | G50: =C49 | H50: =IF(OR(G50="",A50="Savings"),"",C50-G50-F50) | I50: =IF(OR(H50="",G50=0), "", H50/G50)
A51: AI & Big Data | B51: 46235 | C51: =SUMIFS(Month_End!$D:$D,Month_End!$A:$A,B51,Month_End!$B:$B,A51) | D51: =SUMIFS(Transactions_PAC!$H:$H,Transactions_PAC!$B:$B,B51,Transactions_PAC!$C:$C,A51) | E51: =SUMIFS(Transactions_Manual!$E:$E,Transactions_Manual!$B:$B,B51,Transactions_Manual!$C:$C,A51) | F51: =D51+E51 | G51: =C50 | H51: =IF(OR(G51="",A51="Savings"),"",C51-G51-F51) | I51: =IF(OR(H51="",G51=0), "", H51/G51)
A52: AI & Big Data | B52: 46266 | C52: =SUMIFS(Month_End!$D:$D,Month_End!$A:$A,B52,Month_End!$B:$B,A52) | D52: =SUMIFS(Transactions_PAC!$H:$H,Transactions_PAC!$B:$B,B52,Transactions_PAC!$C:$C,A52) | E52: =SUMIFS(Transactions_Manual!$E:$E,Transactions_Manual!$B:$B,B52,Transactions_Manual!$C:$C,A52) | F52: =D52+E52 | G52: =C51 | H52: =IF(OR(G52="",A52="Savings"),"",C52-G52-F52) | I52: =IF(OR(H52="",G52=0), "", H52/G52)
A53: AI & Big Data | B53: 46296 | C53: =SUMIFS(Month_End!$D:$D,Month_End!$A:$A,B53,Month_End!$B:$B,A53) | D53: =SUMIFS(Transactions_PAC!$H:$H,Transactions_PAC!$B:$B,B53,Transactions_PAC!$C:$C,A53) | E53: =SUMIFS(Transactions_Manual!$E:$E,Transactions_Manual!$B:$B,B53,Transactions_Manual!$C:$C,A53) | F53: =D53+E53 | G53: =C52 | H53: =IF(OR(G53="",A53="Savings"),"",C53-G53-F53) | I53: =IF(OR(H53="",G53=0), "", H53/G53)
... A79: AI & Big Data | B79: 47088 | C79: =SUMIFS(Month_End!$D:$D,Month_End!$A:$A,B79,Month_End!$B:$B,A79) | D79: =SUMIFS(Transactions_PAC!$H:$H,Transactions_PAC!$B:$B,B79,Transactions_PAC!$C:$C,A79) | E79: =SUMIFS(Transactions_Manual!$E:$E,Transactions_Manual!$B:$B,B79,Transactions_Manual!$C:$C,A79) | F79: =D79+E79 | G79: =C78 | H79: =IF(OR(G79="",A79="Savings"),"",C79-G79-F79) | I79: =IF(OR(H79="",G79=0), "", H79/G79)
A80: Physical Gold | B80: 45931 | C80: =SUMIFS(Month_End!$D:$D,Month_End!$A:$A,B80,Month_End!$B:$B,A80) | D80: =SUMIFS(Transactions_PAC!$H:$H,Transactions_PAC!$B:$B,B80,Transactions_PAC!$C:$C,A80) | E80: =SUMIFS(Transactions_Manual!$E:$E,Transactions_Manual!$B:$B,B80,Transactions_Manual!$C:$C,A80) | F80: =D80+E80 | H80: =IF(OR(G80="",A80="Savings"),"",C80-G80-F80) | I80: =IF(OR(H80="",G80=0), "", H80/G80)
A81: Physical Gold | B81: 45962 | C81: =SUMIFS(Month_End!$D:$D,Month_End!$A:$A,B81,Month_End!$B:$B,A81) | D81: =SUMIFS(Transactions_PAC!$H:$H,Transactions_PAC!$B:$B,B81,Transactions_PAC!$C:$C,A81) | E81: =SUMIFS(Transactions_Manual!$E:$E,Transactions_Manual!$B:$B,B81,Transactions_Manual!$C:$C,A81) | F81: =D81+E81 | G81: =C80 | H81: =IF(OR(G81="",A81="Savings"),"",C81-G81-F81) | I81: =IF(OR(H81="",G81=0), "", H81/G81)
A82: Physical Gold | B82: 45992 | C82: =SUMIFS(Month_End!$D:$D,Month_End!$A:$A,B82,Month_End!$B:$B,A82) | D82: =SUMIFS(Transactions_PAC!$H:$H,Transactions_PAC!$B:$B,B82,Transactions_PAC!$C:$C,A82) | E82: =SUMIFS(Transactions_Manual!$E:$E,Transactions_Manual!$B:$B,B82,Transactions_Manual!$C:$C,A82) | F82: =D82+E82 | G82: =C81 | H82: =IF(OR(G82="",A82="Savings"),"",C82-G82-F82) | I82: =IF(OR(H82="",G82=0), "", H82/G82)
A83: Physical Gold | B83: 46023 | C83: =SUMIFS(Month_End!$D:$D,Month_End!$A:$A,B83,Month_End!$B:$B,A83) | D83: =SUMIFS(Transactions_PAC!$H:$H,Transactions_PAC!$B:$B,B83,Transactions_PAC!$C:$C,A83) | E83: =SUMIFS(Transactions_Manual!$E:$E,Transactions_Manual!$B:$B,B83,Transactions_Manual!$C:$C,A83) | F83: =D83+E83 | G83: =C82 | H83: =IF(OR(G83="",A83="Savings"),"",C83-G83-F83) | I83: =IF(OR(H83="",G83=0), "", H83/G83)
A84: Physical Gold | B84: 46054 | C84: =SUMIFS(Month_End!$D:$D,Month_End!$A:$A,B84,Month_End!$B:$B,A84) | D84: =SUMIFS(Transactions_PAC!$H:$H,Transactions_PAC!$B:$B,B84,Transactions_PAC!$C:$C,A84) | E84: =SUMIFS(Transactions_Manual!$E:$E,Transactions_Manual!$B:$B,B84,Transactions_Manual!$C:$C,A84) | F84: =D84+E84 | G84: =C83 | H84: =IF(OR(G84="",A84="Savings"),"",C84-G84-F84) | I84: =IF(OR(H84="",G84=0), "", H84/G84)
A85: Physical Gold | B85: 46082 | C85: =SUMIFS(Month_End!$D:$D,Month_End!$A:$A,B85,Month_End!$B:$B,A85) | D85: =SUMIFS(Transactions_PAC!$H:$H,Transactions_PAC!$B:$B,B85,Transactions_PAC!$C:$C,A85) | E85: =SUMIFS(Transactions_Manual!$E:$E,Transactions_Manual!$B:$B,B85,Transactions_Manual!$C:$C,A85) | F85: =D85+E85 | G85: =C84 | H85: =IF(OR(G85="",A85="Savings"),"",C85-G85-F85) | I85: =IF(OR(H85="",G85=0), "", H85/G85)
A86: Physical Gold | B86: 46113 | C86: =SUMIFS(Month_End!$D:$D,Month_End!$A:$A,B86,Month_End!$B:$B,A86) | D86: =SUMIFS(Transactions_PAC!$H:$H,Transactions_PAC!$B:$B,B86,Transactions_PAC!$C:$C,A86) | E86: =SUMIFS(Transactions_Manual!$E:$E,Transactions_Manual!$B:$B,B86,Transactions_Manual!$C:$C,A86) | F86: =D86+E86 | G86: =C85 | H86: =IF(OR(G86="",A86="Savings"),"",C86-G86-F86) | I86: =IF(OR(H86="",G86=0), "", H86/G86)
A87: Physical Gold | B87: 46143 | C87: =SUMIFS(Month_End!$D:$D,Month_End!$A:$A,B87,Month_End!$B:$B,A87) | D87: =SUMIFS(Transactions_PAC!$H:$H,Transactions_PAC!$B:$B,B87,Transactions_PAC!$C:$C,A87) | E87: =SUMIFS(Transactions_Manual!$E:$E,Transactions_Manual!$B:$B,B87,Transactions_Manual!$C:$C,A87) | F87: =D87+E87 | G87: =C86 | H87: =IF(OR(G87="",A87="Savings"),"",C87-G87-F87) | I87: =IF(OR(H87="",G87=0), "", H87/G87)
A88: Physical Gold | B88: 46174 | C88: =SUMIFS(Month_End!$D:$D,Month_End!$A:$A,B88,Month_End!$B:$B,A88) | D88: =SUMIFS(Transactions_PAC!$H:$H,Transactions_PAC!$B:$B,B88,Transactions_PAC!$C:$C,A88) | E88: =SUMIFS(Transactions_Manual!$E:$E,Transactions_Manual!$B:$B,B88,Transactions_Manual!$C:$C,A88) | F88: =D88+E88 | G88: =C87 | H88: =IF(OR(G88="",A88="Savings"),"",C88-G88-F88) | I88: =IF(OR(H88="",G88=0), "", H88/G88)
A89: Physical Gold | B89: 46204 | C89: =SUMIFS(Month_End!$D:$D,Month_End!$A:$A,B89,Month_End!$B:$B,A89) | D89: =SUMIFS(Transactions_PAC!$H:$H,Transactions_PAC!$B:$B,B89,Transactions_PAC!$C:$C,A89) | E89: =SUMIFS(Transactions_Manual!$E:$E,Transactions_Manual!$B:$B,B89,Transactions_Manual!$C:$C,A89) | F89: =D89+E89 | G89: =C88 | H89: =IF(OR(G89="",A89="Savings"),"",C89-G89-F89) | I89: =IF(OR(H89="",G89=0), "", H89/G89)
A90: Physical Gold | B90: 46235 | C90: =SUMIFS(Month_End!$D:$D,Month_End!$A:$A,B90,Month_End!$B:$B,A90) | D90: =SUMIFS(Transactions_PAC!$H:$H,Transactions_PAC!$B:$B,B90,Transactions_PAC!$C:$C,A90) | E90: =SUMIFS(Transactions_Manual!$E:$E,Transactions_Manual!$B:$B,B90,Transactions_Manual!$C:$C,A90) | F90: =D90+E90 | G90: =C89 | H90: =IF(OR(G90="",A90="Savings"),"",C90-G90-F90) | I90: =IF(OR(H90="",G90=0), "", H90/G90)
...

Sheet Dashboard
A1: Portfolio Dashboard | J1: Month | K1: ETF Total | L1: Savings | M1: Total Portfolio | N1: ETF Flow | O1: ETF PnL
J2: 45931 | K2: =SUMIFS(Summary!$C:$C,Summary!$B:$B,$J2,Summary!$A:$A,"<>Savings") | L2: =SUMIFS(Summary!$C:$C,Summary!$B:$B,$J2,Summary!$A:$A,"Savings") | M2: =K2+L2 | N2: =SUMIFS(Summary!$F:$F,Summary!$B:$B,$J2,Summary!$A:$A,"<>Savings") | O2: =SUMIFS(Summary!$H:$H,Summary!$B:$B,$J2,Summary!$A:$A,"<>Savings")
A3: Selected month | B3: 46082 | J3: 45962 | K3: =SUMIFS(Summary!$C:$C,Summary!$B:$B,$J3,Summary!$A:$A,"<>Savings") | L3: =SUMIFS(Summary!$C:$C,Summary!$B:$B,$J3,Summary!$A:$A,"Savings") | M3: =K3+L3 | N3: =SUMIFS(Summary!$F:$F,Summary!$B:$B,$J3,Summary!$A:$A,"<>Savings") | O3: =SUMIFS(Summary!$H:$H,Summary!$B:$B,$J3,Summary!$A:$A,"<>Savings")
J4: 45992 | K4: =SUMIFS(Summary!$C:$C,Summary!$B:$B,$J4,Summary!$A:$A,"<>Savings") | L4: =SUMIFS(Summary!$C:$C,Summary!$B:$B,$J4,Summary!$A:$A,"Savings") | M4: =K4+L4 | N4: =SUMIFS(Summary!$F:$F,Summary!$B:$B,$J4,Summary!$A:$A,"<>Savings") | O4: =SUMIFS(Summary!$H:$H,Summary!$B:$B,$J4,Summary!$A:$A,"<>Savings")
A5: Asset | B5: End_Value | C5: Monthly_Flow | D5: Perf_% | E5: ETF Total | F5: =SUM(B6:B13) | J5: 46023 | K5: =SUMIFS(Summary!$C:$C,Summary!$B:$B,$J5,Summary!$A:$A,"<>Savings") | L5: =SUMIFS(Summary!$C:$C,Summary!$B:$B,$J5,Summary!$A:$A,"Savings") | M5: =K5+L5 | N5: =SUMIFS(Summary!$F:$F,Summary!$B:$B,$J5,Summary!$A:$A,"<>Savings") | O5: =SUMIFS(Summary!$H:$H,Summary!$B:$B,$J5,Summary!$A:$A,"<>Savings")
A6: Core MSCI World | B6: =SUMIFS(Summary!$C:$C,Summary!$A:$A,$A6,Summary!$B:$B,$B$3) | C6: =SUMIFS(Summary!$F:$F,Summary!$A:$A,$A6,Summary!$B:$B,$B$3) | D6: =SUMIFS(Summary!$I:$I,Summary!$A:$A,$A6,Summary!$B:$B,$B$3) | E6: Savings | F6: =B14 | J6: 46054 | K6: =SUMIFS(Summary!$C:$C,Summary!$B:$B,$J6,Summary!$A:$A,"<>Savings") | L6: =SUMIFS(Summary!$C:$C,Summary!$B:$B,$J6,Summary!$A:$A,"Savings") | M6: =K6+L6 | N6: =SUMIFS(Summary!$F:$F,Summary!$B:$B,$J6,Summary!$A:$A,"<>Savings") | O6: =SUMIFS(Summary!$H:$H,Summary!$B:$B,$J6,Summary!$A:$A,"<>Savings")
A7: AI & Big Data | B7: =SUMIFS(Summary!$C:$C,Summary!$A:$A,$A7,Summary!$B:$B,$B$3) | C7: =SUMIFS(Summary!$F:$F,Summary!$A:$A,$A7,Summary!$B:$B,$B$3) | D7: =SUMIFS(Summary!$I:$I,Summary!$A:$A,$A7,Summary!$B:$B,$B$3) | E7: Total Portfolio | F7: =F5+F6 | J7: 46082 | K7: =SUMIFS(Summary!$C:$C,Summary!$B:$B,$J7,Summary!$A:$A,"<>Savings") | L7: =SUMIFS(Summary!$C:$C,Summary!$B:$B,$J7,Summary!$A:$A,"Savings") | M7: =K7+L7 | N7: =SUMIFS(Summary!$F:$F,Summary!$B:$B,$J7,Summary!$A:$A,"<>Savings") | O7: =SUMIFS(Summary!$H:$H,Summary!$B:$B,$J7,Summary!$A:$A,"<>Savings")
A8: Physical Gold | B8: =SUMIFS(Summary!$C:$C,Summary!$A:$A,$A8,Summary!$B:$B,$B$3) | C8: =SUMIFS(Summary!$F:$F,Summary!$A:$A,$A8,Summary!$B:$B,$B$3) | D8: =SUMIFS(Summary!$I:$I,Summary!$A:$A,$A8,Summary!$B:$B,$B$3) | E8: ETF % | F8: =IF(F7=0,0,F5/F7) | J8: 46113 | K8: =SUMIFS(Summary!$C:$C,Summary!$B:$B,$J8,Summary!$A:$A,"<>Savings") | L8: =SUMIFS(Summary!$C:$C,Summary!$B:$B,$J8,Summary!$A:$A,"Savings") | M8: =K8+L8 | N8: =SUMIFS(Summary!$F:$F,Summary!$B:$B,$J8,Summary!$A:$A,"<>Savings") | O8: =SUMIFS(Summary!$H:$H,Summary!$B:$B,$J8,Summary!$A:$A,"<>Savings")
A9: Global Gov Bond | B9: =SUMIFS(Summary!$C:$C,Summary!$A:$A,$A9,Summary!$B:$B,$B$3) | C9: =SUMIFS(Summary!$F:$F,Summary!$A:$A,$A9,Summary!$B:$B,$B$3) | D9: =SUMIFS(Summary!$I:$I,Summary!$A:$A,$A9,Summary!$B:$B,$B$3) | E9: Savings % | F9: =IF(F7=0,0,F6/F7) | J9: 46143 | K9: =SUMIFS(Summary!$C:$C,Summary!$B:$B,$J9,Summary!$A:$A,"<>Savings") | L9: =SUMIFS(Summary!$C:$C,Summary!$B:$B,$J9,Summary!$A:$A,"Savings") | M9: =K9+L9 | N9: =SUMIFS(Summary!$F:$F,Summary!$B:$B,$J9,Summary!$A:$A,"<>Savings") | O9: =SUMIFS(Summary!$H:$H,Summary!$B:$B,$J9,Summary!$A:$A,"<>Savings")
A10: Core EUR Corp Bond | B10: =SUMIFS(Summary!$C:$C,Summary!$A:$A,$A10,Summary!$B:$B,$B$3) | C10: =SUMIFS(Summary!$F:$F,Summary!$A:$A,$A10,Summary!$B:$B,$B$3) | D10: =SUMIFS(Summary!$I:$I,Summary!$A:$A,$A10,Summary!$B:$B,$B$3) | E10: Monthly ETF Flow | F10: =SUM(C6:C13) | J10: 46174 | K10: =SUMIFS(Summary!$C:$C,Summary!$B:$B,$J10,Summary!$A:$A,"<>Savings") | L10: =SUMIFS(Summary!$C:$C,Summary!$B:$B,$J10,Summary!$A:$A,"Savings") | M10: =K10+L10 | N10: =SUMIFS(Summary!$F:$F,Summary!$B:$B,$J10,Summary!$A:$A,"<>Savings") | O10: =SUMIFS(Summary!$H:$H,Summary!$B:$B,$J10,Summary!$A:$A,"<>Savings")
A11: MSCI World Value | B11: =SUMIFS(Summary!$C:$C,Summary!$A:$A,$A11,Summary!$B:$B,$B$3) | C11: =SUMIFS(Summary!$F:$F,Summary!$A:$A,$A11,Summary!$B:$B,$B$3) | D11: =SUMIFS(Summary!$I:$I,Summary!$A:$A,$A11,Summary!$B:$B,$B$3) | E11: Monthly ETF PnL | F11: =SUMIFS(Summary!$H:$H,Summary!$B:$B,$B$3,Summary!$A:$A,"<>Savings") | J11: 46204 | K11: =SUMIFS(Summary!$C:$C,Summary!$B:$B,$J11,Summary!$A:$A,"<>Savings") | L11: =SUMIFS(Summary!$C:$C,Summary!$B:$B,$J11,Summary!$A:$A,"Savings") | M11: =K11+L11 | N11: =SUMIFS(Summary!$F:$F,Summary!$B:$B,$J11,Summary!$A:$A,"<>Savings") | O11: =SUMIFS(Summary!$H:$H,Summary!$B:$B,$J11,Summary!$A:$A,"<>Savings")
A12: MSCI EM | B12: =SUMIFS(Summary!$C:$C,Summary!$A:$A,$A12,Summary!$B:$B,$B$3) | C12: =SUMIFS(Summary!$F:$F,Summary!$A:$A,$A12,Summary!$B:$B,$B$3) | D12: =SUMIFS(Summary!$I:$I,Summary!$A:$A,$A12,Summary!$B:$B,$B$3) | H12: ETF | I12: =F5 | J12: 46235 | K12: =SUMIFS(Summary!$C:$C,Summary!$B:$B,$J12,Summary!$A:$A,"<>Savings") | L12: =SUMIFS(Summary!$C:$C,Summary!$B:$B,$J12,Summary!$A:$A,"Savings") | M12: =K12+L12 | N12: =SUMIFS(Summary!$F:$F,Summary!$B:$B,$J12,Summary!$A:$A,"<>Savings") | O12: =SUMIFS(Summary!$H:$H,Summary!$B:$B,$J12,Summary!$A:$A,"<>Savings")
A13: Defence Tech | B13: =SUMIFS(Summary!$C:$C,Summary!$A:$A,$A13,Summary!$B:$B,$B$3) | C13: =SUMIFS(Summary!$F:$F,Summary!$A:$A,$A13,Summary!$B:$B,$B$3) | D13: =SUMIFS(Summary!$I:$I,Summary!$A:$A,$A13,Summary!$B:$B,$B$3) | H13: Savings | I13: =F6 | J13: 46266 | K13: =SUMIFS(Summary!$C:$C,Summary!$B:$B,$J13,Summary!$A:$A,"<>Savings") | L13: =SUMIFS(Summary!$C:$C,Summary!$B:$B,$J13,Summary!$A:$A,"Savings") | M13: =K13+L13 | N13: =SUMIFS(Summary!$F:$F,Summary!$B:$B,$J13,Summary!$A:$A,"<>Savings") | O13: =SUMIFS(Summary!$H:$H,Summary!$B:$B,$J13,Summary!$A:$A,"<>Savings")
A14: Savings | B14: =SUMIFS(Summary!$C:$C,Summary!$A:$A,$A14,Summary!$B:$B,$B$3) | C14: =SUMIFS(Summary!$F:$F,Summary!$A:$A,$A14,Summary!$B:$B,$B$3) | D14: =SUMIFS(Summary!$I:$I,Summary!$A:$A,$A14,Summary!$B:$B,$B$3) | J14: 46296 | K14: =SUMIFS(Summary!$C:$C,Summary!$B:$B,$J14,Summary!$A:$A,"<>Savings") | L14: =SUMIFS(Summary!$C:$C,Summary!$B:$B,$J14,Summary!$A:$A,"Savings") | M14: =K14+L14 | N14: =SUMIFS(Summary!$F:$F,Summary!$B:$B,$J14,Summary!$A:$A,"<>Savings") | O14: =SUMIFS(Summary!$H:$H,Summary!$B:$B,$J14,Summary!$A:$A,"<>Savings")
J15: 46327 | K15: =SUMIFS(Summary!$C:$C,Summary!$B:$B,$J15,Summary!$A:$A,"<>Savings") | L15: =SUMIFS(Summary!$C:$C,Summary!$B:$B,$J15,Summary!$A:$A,"Savings") | M15: =K15+L15 | N15: =SUMIFS(Summary!$F:$F,Summary!$B:$B,$J15,Summary!$A:$A,"<>Savings") | O15: =SUMIFS(Summary!$H:$H,Summary!$B:$B,$J15,Summary!$A:$A,"<>Savings")
A16: Note: Apr/26 onward PAC is currently zero until you tell me the new monthly PAC amounts. | J16: 46357 | K16: =SUMIFS(Summary!$C:$C,Summary!$B:$B,$J16,Summary!$A:$A,"<>Savings") | L16: =SUMIFS(Summary!$C:$C,Summary!$B:$B,$J16,Summary!$A:$A,"Savings") | M16: =K16+L16 | N16: =SUMIFS(Summary!$F:$F,Summary!$B:$B,$J16,Summary!$A:$A,"<>Savings") | O16: =SUMIFS(Summary!$H:$H,Summary!$B:$B,$J16,Summary!$A:$A,"<>Savings")
J17: 46388 | K17: =SUMIFS(Summary!$C:$C,Summary!$B:$B,$J17,Summary!$A:$A,"<>Savings") | L17: =SUMIFS(Summary!$C:$C,Summary!$B:$B,$J17,Summary!$A:$A,"Savings") | M17: =K17+L17 | N17: =SUMIFS(Summary!$F:$F,Summary!$B:$B,$J17,Summary!$A:$A,"<>Savings") | O17: =SUMIFS(Summary!$H:$H,Summary!$B:$B,$J17,Summary!$A:$A,"<>Savings")
J18: 46419 | K18: =SUMIFS(Summary!$C:$C,Summary!$B:$B,$J18,Summary!$A:$A,"<>Savings") | L18: =SUMIFS(Summary!$C:$C,Summary!$B:$B,$J18,Summary!$A:$A,"Savings") | M18: =K18+L18 | N18: =SUMIFS(Summary!$F:$F,Summary!$B:$B,$J18,Summary!$A:$A,"<>Savings") | O18: =SUMIFS(Summary!$H:$H,Summary!$B:$B,$J18,Summary!$A:$A,"<>Savings")
J19: 46447 | K19: =SUMIFS(Summary!$C:$C,Summary!$B:$B,$J19,Summary!$A:$A,"<>Savings") | L19: =SUMIFS(Summary!$C:$C,Summary!$B:$B,$J19,Summary!$A:$A,"Savings") | M19: =K19+L19 | N19: =SUMIFS(Summary!$F:$F,Summary!$B:$B,$J19,Summary!$A:$A,"<>Savings") | O19: =SUMIFS(Summary!$H:$H,Summary!$B:$B,$J19,Summary!$A:$A,"<>Savings")
J20: 46478 | K20: =SUMIFS(Summary!$C:$C,Summary!$B:$B,$J20,Summary!$A:$A,"<>Savings") | L20: =SUMIFS(Summary!$C:$C,Summary!$B:$B,$J20,Summary!$A:$A,"Savings") | M20: =K20+L20 | N20: =SUMIFS(Summary!$F:$F,Summary!$B:$B,$J20,Summary!$A:$A,"<>Savings") | O20: =SUMIFS(Summary!$H:$H,Summary!$B:$B,$J20,Summary!$A:$A,"<>Savings")
J21: 46508 | K21: =SUMIFS(Summary!$C:$C,Summary!$B:$B,$J21,Summary!$A:$A,"<>Savings") | L21: =SUMIFS(Summary!$C:$C,Summary!$B:$B,$J21,Summary!$A:$A,"Savings") | M21: =K21+L21 | N21: =SUMIFS(Summary!$F:$F,Summary!$B:$B,$J21,Summary!$A:$A,"<>Savings") | O21: =SUMIFS(Summary!$H:$H,Summary!$B:$B,$J21,Summary!$A:$A,"<>Savings")
J22: 46539 | K22: =SUMIFS(Summary!$C:$C,Summary!$B:$B,$J22,Summary!$A:$A,"<>Savings") | L22: =SUMIFS(Summary!$C:$C,Summary!$B:$B,$J22,Summary!$A:$A,"Savings") | M22: =K22+L22 | N22: =SUMIFS(Summary!$F:$F,Summary!$B:$B,$J22,Summary!$A:$A,"<>Savings") | O22: =SUMIFS(Summary!$H:$H,Summary!$B:$B,$J22,Summary!$A:$A,"<>Savings")
J23: 46569 | K23: =SUMIFS(Summary!$C:$C,Summary!$B:$B,$J23,Summary!$A:$A,"<>Savings") | L23: =SUMIFS(Summary!$C:$C,Summary!$B:$B,$J23,Summary!$A:$A,"Savings") | M23: =K23+L23 | N23: =SUMIFS(Summary!$F:$F,Summary!$B:$B,$J23,Summary!$A:$A,"<>Savings") | O23: =SUMIFS(Summary!$H:$H,Summary!$B:$B,$J23,Summary!$A:$A,"<>Savings")
J24: 46600 | K24: =SUMIFS(Summary!$C:$C,Summary!$B:$B,$J24,Summary!$A:$A,"<>Savings") | L24: =SUMIFS(Summary!$C:$C,Summary!$B:$B,$J24,Summary!$A:$A,"Savings") | M24: =K24+L24 | N24: =SUMIFS(Summary!$F:$F,Summary!$B:$B,$J24,Summary!$A:$A,"<>Savings") | O24: =SUMIFS(Summary!$H:$H,Summary!$B:$B,$J24,Summary!$A:$A,"<>Savings")
J25: 46631 | K25: =SUMIFS(Summary!$C:$C,Summary!$B:$B,$J25,Summary!$A:$A,"<>Savings") | L25: =SUMIFS(Summary!$C:$C,Summary!$B:$B,$J25,Summary!$A:$A,"Savings") | M25: =K25+L25 | N25: =SUMIFS(Summary!$F:$F,Summary!$B:$B,$J25,Summary!$A:$A,"<>Savings") | O25: =SUMIFS(Summary!$H:$H,Summary!$B:$B,$J25,Summary!$A:$A,"<>Savings")
J26: 46661 | K26: =SUMIFS(Summary!$C:$C,Summary!$B:$B,$J26,Summary!$A:$A,"<>Savings") | L26: =SUMIFS(Summary!$C:$C,Summary!$B:$B,$J26,Summary!$A:$A,"Savings") | M26: =K26+L26 | N26: =SUMIFS(Summary!$F:$F,Summary!$B:$B,$J26,Summary!$A:$A,"<>Savings") | O26: =SUMIFS(Summary!$H:$H,Summary!$B:$B,$J26,Summary!$A:$A,"<>Savings")
J27: 46692 | K27: =SUMIFS(Summary!$C:$C,Summary!$B:$B,$J27,Summary!$A:$A,"<>Savings") | L27: =SUMIFS(Summary!$C:$C,Summary!$B:$B,$J27,Summary!$A:$A,"Savings") | M27: =K27+L27 | N27: =SUMIFS(Summary!$F:$F,Summary!$B:$B,$J27,Summary!$A:$A,"<>Savings") | O27: =SUMIFS(Summary!$H:$H,Summary!$B:$B,$J27,Summary!$A:$A,"<>Savings")
J28: 46722 | K28: =SUMIFS(Summary!$C:$C,Summary!$B:$B,$J28,Summary!$A:$A,"<>Savings") | L28: =SUMIFS(Summary!$C:$C,Summary!$B:$B,$J28,Summary!$A:$A,"Savings") | M28: =K28+L28 | N28: =SUMIFS(Summary!$F:$F,Summary!$B:$B,$J28,Summary!$A:$A,"<>Savings") | O28: =SUMIFS(Summary!$H:$H,Summary!$B:$B,$J28,Summary!$A:$A,"<>Savings")
... J37: 46997 | K37: =SUMIFS(Summary!$C:$C,Summary!$B:$B,$J37,Summary!$A:$A,"<>Savings") | L37: =SUMIFS(Summary!$C:$C,Summary!$B:$B,$J37,Summary!$A:$A,"Savings") | M37: =K37+L37 | N37: =SUMIFS(Summary!$F:$F,Summary!$B:$B,$J37,Summary!$A:$A,"<>Savings") | O37: =SUMIFS(Summary!$H:$H,Summary!$B:$B,$J37,Summary!$A:$A,"<>Savings")
